<?xml version='1.0'?>

<robot name="ultra_udacity_bot" xmlns:xacro="http://www.ros.org/wiki/xacro">
  
  <xacro:include filename="$(find udacity_bot)/urdf/ultra_udacity_bot.gazebo" />

  <link name="robot_footprint"></link>

  <joint name="robot_footprint_joint" type="fixed">
    <origin xyz="0 0 0" rpy="0 0 0" />
    <parent link="robot_footprint"/>
    <child link="chassis" />
  </joint>

  <link name='chassis'>
    <pose>0 0 0.1 0 0 0</pose>

    <material>Gazebo/Black</material>

    <inertial>
      <mass value="1.0"/>
      <origin xyz="0.0 0 0" rpy=" 0 0 0"/>
      <inertia
          ixx="0.1" ixy="0" ixz="0"
          iyy="0.1" iyz="0"
          izz="0.1"
      />
    </inertial>

    <collision name='collision'>
      <origin xyz="0 0 -.08" rpy=" 0 0 210"/> 
      <geometry>
        <mesh filename="package://udacity_bot/meshes/udacity.dae"  scale=".45 .45 .45"/>
      </geometry>
    </collision>

    <visual name='chassis_visual'>
      <origin xyz="0 0 -.08" rpy=" 0 0 210"/>
      <geometry>
      	<!-- model is 60 mm tall, 20 mm thick -->
        <mesh filename="package://udacity_bot/meshes/udacity.dae" scale=".45 .45 .45"/>
      </geometry>
    </visual>

  </link>

  <link name='left_wheel'>
    <pose>0 0 0 0 0 0</pose>

    <inertial>
      <mass value="5.0"/>
      <origin xyz="0.0 0 0" rpy=" 0 1.5707 1.5707"/>
      <inertia
          ixx="0.1" ixy="0" ixz="0"
          iyy="0.1" iyz="0"
          izz="0.1"
      />
    </inertial>

    <collision name='left_wheel_collision'>
      <origin xyz="0 0 0" rpy=" 0 1.5707 1.5707"/> 
      <geometry>
        <cylinder radius="0.05" length="0.05"/>
      </geometry>
    </collision>

    <visual name='left_wheel_visual'>
      <origin xyz="0 0 0" rpy=" 0 1.5707 1.5707"/>
      <geometry>
        <cylinder radius="0.05" length="0.05"/>
      </geometry>
    </visual>

  </link>

  <link name='right_wheel'>
    <pose>0 0 0 0 0 0</pose>

    <inertial>
      <mass value="5.0"/>
      <origin xyz="0.0 0 0" rpy=" 0 1.5707 -1.5707"/>
      <inertia
          ixx="0.1" ixy="0" ixz="0"
          iyy="0.1" iyz="0"
          izz="0.1"
      />
    </inertial>

    <collision name='right_wheel_collision'>
      <origin xyz="0 0 0" rpy=" 0 1.5707 -1.5707"/> 
      <geometry>
        <cylinder radius="0.05" length="0.05"/>
      </geometry>
    </collision>

    <visual name='right_wheel_visual'>
      <origin xyz="0 0 0" rpy=" 0 1.5707 -1.5707"/>
      <geometry>
        <cylinder radius="0.05" length="0.05"/>
      </geometry>
    </visual>

  </link>

  <link name='rear_caster'>
    <pose>0 0 0 0 0 0</pose>

    <inertial>
      <mass value="5.0"/>
      <origin xyz="0.0 0 0" rpy=" 0 1.5707 -1.5707"/>
      <inertia
          ixx="0.1" ixy="0" ixz="0"
          iyy="0.1" iyz="0"
          izz="0.1"
      />
    </inertial>

    <collision name='back_caster_collision'>
      <origin xyz="0 0 0" rpy=" 0 0 0"/>
      <geometry>
        <sphere radius="0.050"/>
      </geometry>
      <surface>
        <friction>
          <ode>
            <mu>0</mu>
            <mu2>0</mu2>
            <slip1>1.0</slip1>
            <slip2>1.0</slip2>
          </ode>
        </friction>
      </surface>
    </collision>

    <visual name='back_caster_visual'>
      <origin xyz="0 0 0" rpy=" 0 0 0"/>
      <geometry>
        <sphere radius="0.05"/>
      </geometry>
    </visual>

  </link>

  <joint type="fixed" name="rear_caster_link">
    <origin xyz="-0.25 -.04 -0.05" rpy=" 0 0 0"/>
    <child link="rear_caster"/>
    <parent link="chassis"/>
  </joint>


  <joint type="continuous" name="left_wheel_hinge">
    <origin xyz="0 0.15 -.05" rpy="0 0 0"/>
    <child link="left_wheel"/>
    <parent link="chassis"/>
    <axis xyz="0 1 0" rpy="0 0 0"/>
    <limit effort="10000" velocity="1000"/>
    <joint_properties damping="1.0" friction="1.0"/>
  </joint>

  <joint type="continuous" name="right_wheel_hinge">
    <origin xyz="0 -0.15 -.05" rpy="0 0 0"/>
    <child link="right_wheel"/>
    <parent link="chassis"/>
    <axis xyz="0 1 0" rpy="0 0 0"/>
    <limit effort="10000" velocity="1000"/>
    <joint_properties damping="1.0" friction="1.0"/>
  </joint>
  
  <link name="camera">
    <pose>0 0 0 0 0 0</pose>

    <inertial>
      <mass value="1.0"/>
      <origin xyz="0 0 0" rpy=" 0 0 0"/>
      <inertia
          ixx="1e-6" ixy="0" ixz="0"
          iyy="1e-6" iyz="0"
          izz="1e-6"
      />
    </inertial>

    <collision name='camera_collision'>
      <origin xyz="0 0 0" rpy=" 0 0 0"/> 
      <geometry>
        <box size="0.05 0.05 0.05"/>
      </geometry>
    </collision>

    <visual name='camera_visual'>
      <origin xyz="0 0 0" rpy=" 0 0 0"/> 
      <geometry>
        <box size="0.05 0.05 0.05"/>
      </geometry>
    </visual>

  </link>

  <joint type="fixed" name="camera_joint">
    <origin xyz="0.15 0 -.03" rpy="0 0 0"/>
    <child link="camera"/>
    <parent link="chassis"/>
  </joint>

  <link name="hokuyo">
    <pose>0 0 0 0 0 0</pose>

    <inertial>
      <mass value="1.0"/>
      <origin xyz="0 0 0" rpy=" 0 0 0"/>
      <inertia
          ixx="1e-6" ixy="0" ixz="0"
          iyy="1e-6" iyz="0"
          izz="1e-6"
      />
    </inertial>

    <collision name="hokuyo_collision">
      <origin xyz="0 0 0" rpy=" 0 0 0"/> 
      <geometry>
        <box size="0.1 0.1 0.1"/>
      </geometry>
    </collision>

    <visual name="hokuyo_visual">
      <origin xyz="0 0 0" rpy=" 0 0 0"/> 
      <geometry>
        <mesh filename="package://udacity_bot/meshes/hokuyo.dae"/>
      </geometry>
    </visual>

  </link>

  <joint type="fixed" name="hokuyo_joint">
    <origin xyz="0 0 0.05" rpy="0 0 0"/>
    <child link="hokuyo"/>
    <parent link="chassis"/>
  </joint>

</robot>
